<?xml version="1.0" encoding="utf-8"?>
<robot
  name="ASM-1">
  <link
    name="base">
    <inertial>
      <origin
        xyz="8.0119E-17 -2.0531E-17 -1.5689E-05"
        rpy="0 0 0" />
      <mass
        value="0.31685" />
      <inertia
        ixx="0.00024197"
        ixy="-1.8731E-07"
        ixz="-7.1634E-22"
        iyy="0.00046096"
        iyz="1.6138E-21"
        izz="0.00064903" />
    </inertial>
    <visual>
      <origin
        xyz="0 0 0"
        rpy="0 0 0" />
      <geometry>
        <mesh
          filename="package://ASM-1/meshes/base.STL" />
      </geometry>
      <material
        name="">
        <color
          rgba="0.75294 0.75294 0.75294 1" />
      </material>
    </visual>
    <collision>
      <origin
        xyz="0 0 0"
        rpy="0 0 0" />
      <geometry>
        <mesh
          filename="package://ASM-1/meshes/base.STL" />
      </geometry>
    </collision>
  </link>
  <link
    name="Empty_Link1-1">
    <inertial>
      <origin
        xyz="-5.0235E-05 0.033 -5.0235E-05"
        rpy="0 0 0" />
      <mass
        value="0.019731" />
      <inertia
        ixx="9.7709E-06"
        ixy="2.916E-08"
        ixz="1.2047E-19"
        iyy="1.2373E-05"
        iyz="-2.916E-08"
        izz="9.7709E-06" />
    </inertial>
    <visual>
      <origin
        xyz="0 0 0"
        rpy="0 0 0" />
      <geometry>
        <mesh
          filename="package://ASM-1/meshes/Empty_Link1-1.STL" />
      </geometry>
      <material
        name="">
        <color
          rgba="0.75294 0.75294 0.75294 1" />
      </material>
    </visual>
    <collision>
      <origin
        xyz="0 0 0"
        rpy="0 0 0" />
      <geometry>
        <mesh
          filename="package://ASM-1/meshes/Empty_Link1-1.STL" />
      </geometry>
    </collision>
  </link>
  <joint
    name="joint1-1"
    type="revolute">
    <origin
      xyz="0.12051 0.065506 0"
      rpy="0 0 -0.7854" />
    <parent
      link="base" />
    <child
      link="Empty_Link1-1" />
    <axis
      xyz="0 0 -1" />
    <limit
      lower="-1.05"
      upper="1.05"
      effort="0"
      velocity="0" />
  </joint>
  <link
    name="Empty_Link2-1">
    <inertial>
      <origin
        xyz="2.7756E-17 0.047 0.00065737"
        rpy="0 0 0" />
      <mass
        value="0.073611" />
      <inertia
        ixx="1.2766E-05"
        ixy="1.5138E-08"
        ixz="-9.573E-22"
        iyy="1.3909E-05"
        iyz="-1.8249E-23"
        izz="2.1644E-05" />
    </inertial>
    <visual>
      <origin
        xyz="0 0 0"
        rpy="0 0 0" />
      <geometry>
        <mesh
          filename="package://ASM-1/meshes/Empty_Link2-1.STL" />
      </geometry>
      <material
        name="">
        <color
          rgba="0.75294 0.75294 0.75294 1" />
      </material>
    </visual>
    <collision>
      <origin
        xyz="0 0 0"
        rpy="0 0 0" />
      <geometry>
        <mesh
          filename="package://ASM-1/meshes/Empty_Link2-1.STL" />
      </geometry>
    </collision>
  </link>
  <joint
    name="joint2-1"
    type="revolute">
    <origin
      xyz="0 0.066 0"
      rpy="0 0 0" />
    <parent
      link="Empty_Link1-1" />
    <child
      link="Empty_Link2-1" />
    <axis
      xyz="1 0 0" />
    <limit
      lower="-1.57"
      upper="1.57"
      effort="0"
      velocity="0" />
  </joint>
  <link
    name="Empty_Link3-1">
    <inertial>
      <origin
        xyz="4.9997E-05 0.090046 0.010444"
        rpy="0 0 0" />
      <mass
        value="0.042552" />
      <inertia
        ixx="2.1042E-05"
        ixy="-7.5974E-12"
        ixz="3.4741E-12"
        iyy="8.3412E-06"
        iyz="-7.4831E-07"
        izz="2.4944E-05" />
    </inertial>
    <visual>
      <origin
        xyz="0 0 0"
        rpy="0 0 0" />
      <geometry>
        <mesh
          filename="package://ASM-1/meshes/Empty_Link3-1.STL" />
      </geometry>
      <material
        name="">
        <color
          rgba="0.75294 0.75294 0.75294 1" />
      </material>
    </visual>
    <collision>
      <origin
        xyz="0 0 0"
        rpy="0 0 0" />
      <geometry>
        <mesh
          filename="package://ASM-1/meshes/Empty_Link3-1.STL" />
      </geometry>
    </collision>
  </link>
  <joint
    name="joint3-1"
    type="revolute">
    <origin
      xyz="0 0.094 0"
      rpy="-1.5708 0 0" />
    <parent
      link="Empty_Link2-1" />
    <child
      link="Empty_Link3-1" />
    <axis
      xyz="-1 0 0" />
    <limit
      lower="-1.57"
      upper="1.57"
      effort="0"
      velocity="0" />
  </joint>
  <link
    name="Empty_Link1-2">
    <inertial>
      <origin
        xyz="-5.02346878693202E-05 0.0330000000000001 -5.02346878692717E-05"
        rpy="0 0 0" />
      <mass
        value="0.019731071348658" />
      <inertia
        ixx="9.77086440607924E-06"
        ixy="2.91599083472466E-08"
        ixz="1.24805402960545E-19"
        iyy="1.23734036568865E-05"
        iyz="-2.91599083472444E-08"
        izz="9.77086440607927E-06" />
    </inertial>
    <visual>
      <origin
        xyz="0 0 0"
        rpy="0 0 0" />
      <geometry>
        <mesh
          filename="package://ASM-1/meshes/Empty_Link1-2.STL" />
      </geometry>
      <material
        name="">
        <color
          rgba="0.752941176470588 0.752941176470588 0.752941176470588 1" />
      </material>
    </visual>
    <collision>
      <origin
        xyz="0 0 0"
        rpy="0 0 0" />
      <geometry>
        <mesh
          filename="package://ASM-1/meshes/Empty_Link1-2.STL" />
      </geometry>
    </collision>
  </link>
  <joint
    name="joint1-2"
    type="revolute">
    <origin
      xyz="0 0.116 0"
      rpy="0 0 0" />
    <parent
      link="base" />
    <child
      link="Empty_Link1-2" />
    <axis
      xyz="0 0 -1" />
    <limit
      lower="-1.05"
      upper="1.05"
      effort="0"
      velocity="0" />
  </joint>
  <link
    name="Empty_Link2-2">
    <inertial>
      <origin
        xyz="2.25108720576213E-05 0.047 0.000657512135363084"
        rpy="0 0 0" />
      <mass
        value="0.073610808678494" />
      <inertia
        ixx="1.27657759015739E-05"
        ixy="-7.04369358369001E-22"
        ixz="-2.65935038353795E-23"
        iyy="1.39088073615343E-05"
        iyz="-3.63365746503431E-11"
        izz="2.1644430327163E-05" />
    </inertial>
    <visual>
      <origin
        xyz="0 0 0"
        rpy="0 0 0" />
      <geometry>
        <mesh
          filename="package://ASM-1/meshes/Empty_Link2-2.STL" />
      </geometry>
      <material
        name="">
        <color
          rgba="0.752941176470588 0.752941176470588 0.752941176470588 1" />
      </material>
    </visual>
    <collision>
      <origin
        xyz="0 0 0"
        rpy="0 0 0" />
      <geometry>
        <mesh
          filename="package://ASM-1/meshes/Empty_Link2-2.STL" />
      </geometry>
    </collision>
  </link>
  <joint
    name="joint2-2"
    type="revolute">
    <origin
      xyz="0 0.066 0"
      rpy="0 0 0" />
    <parent
      link="Empty_Link1-2" />
    <child
      link="Empty_Link2-2" />
    <axis
      xyz="1 0 0" />
    <limit
      lower="-1.57"
      upper="1.57"
      effort="0"
      velocity="0" />
  </joint>
  <link
    name="Empty_Link3-2">
    <inertial>
      <origin
        xyz="4.99966505388746E-05 0.0900463291127983 0.010443724929981"
        rpy="0 0 0" />
      <mass
        value="0.0425517560330798" />
      <inertia
        ixx="2.10424480932041E-05"
        ixy="-7.60273567051125E-12"
        ixz="3.4765113891799E-12"
        iyy="8.34117266397958E-06"
        iyz="-7.48309280558835E-07"
        izz="2.49437221252634E-05" />
    </inertial>
    <visual>
      <origin
        xyz="0 0 0"
        rpy="0 0 0" />
      <geometry>
        <mesh
          filename="package://ASM-1/meshes/Empty_Link3-2.STL" />
      </geometry>
      <material
        name="">
        <color
          rgba="0.752941176470588 0.752941176470588 0.752941176470588 1" />
      </material>
    </visual>
    <collision>
      <origin
        xyz="0 0 0"
        rpy="0 0 0" />
      <geometry>
        <mesh
          filename="package://ASM-1/meshes/Empty_Link3-2.STL" />
      </geometry>
    </collision>
  </link>
  <joint
    name="joint3-2"
    type="revolute">
    <origin
      xyz="0 0.094 0"
      rpy="-1.5708 0 0" />
    <parent
      link="Empty_Link2-2" />
    <child
      link="Empty_Link3-2" />
    <axis
      xyz="1 0 0" />
    <limit
      lower="-1.57"
      upper="1.57"
      effort="0"
      velocity="0" />
  </joint>
  <link
    name="Empty_Link1-3">
    <inertial>
      <origin
        xyz="-5.02346878681059E-05 0.033 -5.02346878692821E-05"
        rpy="0 0 0" />
      <mass
        value="0.019731071348658" />
      <inertia
        ixx="9.77086440607927E-06"
        ixy="2.91599083472445E-08"
        ixz="1.26921613444854E-19"
        iyy="1.23734036568865E-05"
        iyz="-2.91599083472381E-08"
        izz="9.77086440607927E-06" />
    </inertial>
    <visual>
      <origin
        xyz="0 0 0"
        rpy="0 0 0" />
      <geometry>
        <mesh
          filename="package://ASM-1/meshes/Empty_Link1-3.STL" />
      </geometry>
      <material
        name="">
        <color
          rgba="0.752941176470588 0.752941176470588 0.752941176470588 1" />
      </material>
    </visual>
    <collision>
      <origin
        xyz="0 0 0"
        rpy="0 0 0" />
      <geometry>
        <mesh
          filename="package://ASM-1/meshes/Empty_Link1-3.STL" />
      </geometry>
    </collision>
  </link>
  <joint
    name="joint1-3"
    type="revolute">
    <origin
      xyz="-0.12051 0.065506 0"
      rpy="0 0 0.7854" />
    <parent
      link="base" />
    <child
      link="Empty_Link1-3" />
    <axis
      xyz="0 0 -1" />
    <limit
      lower="-1.05"
      upper="1.05"
      effort="0"
      velocity="0" />
  </joint>
  <link
    name="Empty_Link2-3">
    <inertial>
      <origin
        xyz="-2.25108720576517E-05 0.047 0.000657512135363084"
        rpy="0 0 0" />
      <mass
        value="0.0736108086784939" />
      <inertia
        ixx="1.27657759015739E-05"
        ixy="-8.470329472543E-22"
        ixz="-8.4848217770916E-22"
        iyy="1.39088073615343E-05"
        iyz="3.63365746501307E-11"
        izz="2.1644430327163E-05" />
    </inertial>
    <visual>
      <origin
        xyz="0 0 0"
        rpy="0 0 0" />
      <geometry>
        <mesh
          filename="package://ASM-1/meshes/Empty_Link2-3.STL" />
      </geometry>
      <material
        name="">
        <color
          rgba="0.752941176470588 0.752941176470588 0.752941176470588 1" />
      </material>
    </visual>
    <collision>
      <origin
        xyz="0 0 0"
        rpy="0 0 0" />
      <geometry>
        <mesh
          filename="package://ASM-1/meshes/Empty_Link2-3.STL" />
      </geometry>
    </collision>
  </link>
  <joint
    name="joint2-3"
    type="revolute">
    <origin
      xyz="0 0.066 0"
      rpy="0 0 0" />
    <parent
      link="Empty_Link1-3" />
    <child
      link="Empty_Link2-3" />
    <axis
      xyz="-1 0 0" />
    <limit
      lower="-1.57"
      upper="1.57"
      effort="0"
      velocity="0" />
  </joint>
  <link
    name="Empty_Link3-3">
    <inertial>
      <origin
        xyz="4.99966688655984E-05 0.0900463290285191 0.0104437249548177"
        rpy="0 0 0" />
      <mass
        value="0.0425517554776166" />
      <inertia
        ixx="2.10424480740807E-05"
        ixy="-7.59739057597617E-12"
        ixz="3.47413320408595E-12"
        iyy="8.34117254759515E-06"
        iyz="-7.48309278499939E-07"
        izz="2.49437219866352E-05" />
    </inertial>
    <visual>
      <origin
        xyz="0 0 0"
        rpy="0 0 0" />
      <geometry>
        <mesh
          filename="package://ASM-1/meshes/Empty_Link3-3.STL" />
      </geometry>
      <material
        name="">
        <color
          rgba="0.752941176470588 0.752941176470588 0.752941176470588 1" />
      </material>
    </visual>
    <collision>
      <origin
        xyz="0 0 0"
        rpy="0 0 0" />
      <geometry>
        <mesh
          filename="package://ASM-1/meshes/Empty_Link3-3.STL" />
      </geometry>
    </collision>
  </link>
  <joint
    name="joint3-3"
    type="revolute">
    <origin
      xyz="0 0.094 0"
      rpy="-1.5708 0 0" />
    <parent
      link="Empty_Link2-3" />
    <child
      link="Empty_Link3-3" />
    <axis
      xyz="-1 0 0" />
    <limit
      lower="-1.57"
      upper="1.57"
      effort="0"
      velocity="0" />
  </joint>
  <link
    name="Empty_Link1-4">
    <inertial>
      <origin
        xyz="-5.02346878693341E-05 0.0329999999999999 -5.02346878692751E-05"
        rpy="0 0 0" />
      <mass
        value="0.019731071348658" />
      <inertia
        ixx="9.77086440607928E-06"
        ixy="2.91599083472385E-08"
        ixz="1.25175842968173E-19"
        iyy="1.23734036568865E-05"
        iyz="-2.91599083472377E-08"
        izz="9.77086440607929E-06" />
    </inertial>
    <visual>
      <origin
        xyz="0 0 0"
        rpy="0 0 0" />
      <geometry>
        <mesh
          filename="package://ASM-1/meshes/Empty_Link1-4.STL" />
      </geometry>
      <material
        name="">
        <color
          rgba="0.752941176470588 0.752941176470588 0.752941176470588 1" />
      </material>
    </visual>
    <collision>
      <origin
        xyz="0 0 0"
        rpy="0 0 0" />
      <geometry>
        <mesh
          filename="package://ASM-1/meshes/Empty_Link1-4.STL" />
      </geometry>
    </collision>
  </link>
  <joint
    name="joint1-4"
    type="revolute">
    <origin
      xyz="-0.12051 -0.065506 0"
      rpy="0 0 2.3562" />
    <parent
      link="base" />
    <child
      link="Empty_Link1-4" />
    <axis
      xyz="0 0 -1" />
    <limit
      lower="-1.05"
      upper="1.05"
      effort="0"
      velocity="0" />
  </joint>
  <link
    name="Empty_Link2-4">
    <inertial>
      <origin
        xyz="-4.16333634234434E-17 0.047 0.000657371115648689"
        rpy="0 0 0" />
      <mass
        value="0.0736108086784939" />
      <inertia
        ixx="1.27657759015739E-05"
        ixy="1.5137622231201E-08"
        ixz="-3.00289212737499E-22"
        iyy="1.39088073615343E-05"
        iyz="9.0877177035597E-22"
        izz="2.1644430327163E-05" />
    </inertial>
    <visual>
      <origin
        xyz="0 0 0"
        rpy="0 0 0" />
      <geometry>
        <mesh
          filename="package://ASM-1/meshes/Empty_Link2-4.STL" />
      </geometry>
      <material
        name="">
        <color
          rgba="0.752941176470588 0.752941176470588 0.752941176470588 1" />
      </material>
    </visual>
    <collision>
      <origin
        xyz="0 0 0"
        rpy="0 0 0" />
      <geometry>
        <mesh
          filename="package://ASM-1/meshes/Empty_Link2-4.STL" />
      </geometry>
    </collision>
  </link>
  <joint
    name="joint2-4"
    type="revolute">
    <origin
      xyz="0 0.066 0"
      rpy="0 0 0" />
    <parent
      link="Empty_Link1-4" />
    <child
      link="Empty_Link2-4" />
    <axis
      xyz="1 0 0" />
    <limit
      lower="-1.57"
      upper="1.57"
      effort="0"
      velocity="0" />
  </joint>
  <link
    name="Empty_Link3-4">
    <inertial>
      <origin
        xyz="4.99966688654874E-05 0.0900463290285193 0.0104437249548173"
        rpy="0 0 0" />
      <mass
        value="0.0425517554776168" />
      <inertia
        ixx="2.10424480740807E-05"
        ixy="-7.59739058801992E-12"
        ixz="3.47413320832111E-12"
        iyy="8.3411725475952E-06"
        iyz="-7.48309278499937E-07"
        izz="2.49437219866352E-05" />
    </inertial>
    <visual>
      <origin
        xyz="0 0 0"
        rpy="0 0 0" />
      <geometry>
        <mesh
          filename="package://ASM-1/meshes/Empty_Link3-4.STL" />
      </geometry>
      <material
        name="">
        <color
          rgba="0.752941176470588 0.752941176470588 0.752941176470588 1" />
      </material>
    </visual>
    <collision>
      <origin
        xyz="0 0 0"
        rpy="0 0 0" />
      <geometry>
        <mesh
          filename="package://ASM-1/meshes/Empty_Link3-4.STL" />
      </geometry>
    </collision>
  </link>
  <joint
    name="joint3-4"
    type="revolute">
    <origin
      xyz="0 0.094 0"
      rpy="-1.5708 0 0" />
    <parent
      link="Empty_Link2-4" />
    <child
      link="Empty_Link3-4" />
    <axis
      xyz="-1 0 0" />
    <limit
      lower="-1.57"
      upper="1.57"
      effort="0"
      velocity="0" />
  </joint>
  <link
    name="Empty_Link1-5">
    <inertial>
      <origin
        xyz="-5.02346878692846E-05 0.033 -5.02346878692612E-05"
        rpy="0 0 0" />
      <mass
        value="0.019731071348658" />
      <inertia
        ixx="9.77086440607928E-06"
        ixy="2.91599083472416E-08"
        ixz="1.2460847700495E-19"
        iyy="1.23734036568865E-05"
        iyz="-2.91599083472407E-08"
        izz="9.77086440607927E-06" />
    </inertial>
    <visual>
      <origin
        xyz="0 0 0"
        rpy="0 0 0" />
      <geometry>
        <mesh
          filename="package://ASM-1/meshes/Empty_Link1-5.STL" />
      </geometry>
      <material
        name="">
        <color
          rgba="0.752941176470588 0.752941176470588 0.752941176470588 1" />
      </material>
    </visual>
    <collision>
      <origin
        xyz="0 0 0"
        rpy="0 0 0" />
      <geometry>
        <mesh
          filename="package://ASM-1/meshes/Empty_Link1-5.STL" />
      </geometry>
    </collision>
  </link>
  <joint
    name="joint1-5"
    type="revolute">
    <origin
      xyz="0 -0.116 0"
      rpy="0 0 -3.1416" />
    <parent
      link="base" />
    <child
      link="Empty_Link1-5" />
    <axis
      xyz="0 0 -1" />
    <limit
      lower="-1.05"
      upper="1.05"
      effort="0"
      velocity="0" />
  </joint>
  <link
    name="Empty_Link2-5">
    <inertial>
      <origin
        xyz="-2.25108720578158E-05 0.047 0.000657512135363084"
        rpy="0 0 0" />
      <mass
        value="0.0736108086784939" />
      <inertia
        ixx="1.27657759015739E-05"
        ixy="1.14572117382462E-21"
        ixz="2.33601504355852E-21"
        iyy="1.39088073615343E-05"
        iyz="3.63365746527667E-11"
        izz="2.1644430327163E-05" />
    </inertial>
    <visual>
      <origin
        xyz="0 0 0"
        rpy="0 0 0" />
      <geometry>
        <mesh
          filename="package://ASM-1/meshes/Empty_Link2-5.STL" />
      </geometry>
      <material
        name="">
        <color
          rgba="0.752941176470588 0.752941176470588 0.752941176470588 1" />
      </material>
    </visual>
    <collision>
      <origin
        xyz="0 0 0"
        rpy="0 0 0" />
      <geometry>
        <mesh
          filename="package://ASM-1/meshes/Empty_Link2-5.STL" />
      </geometry>
    </collision>
  </link>
  <joint
    name="joint2-5"
    type="revolute">
    <origin
      xyz="0 0.066 0"
      rpy="0 0 0" />
    <parent
      link="Empty_Link1-5" />
    <child
      link="Empty_Link2-5" />
    <axis
      xyz="-1 0 0" />
    <limit
      lower="-1.57"
      upper="1.57"
      effort="0"
      velocity="0" />
  </joint>
  <link
    name="Empty_Link3-5">
    <inertial>
      <origin
        xyz="4.99966505387937E-05 0.0900463291127983 0.0104437249299811"
        rpy="0 0 0" />
      <mass
        value="0.0425517560330798" />
      <inertia
        ixx="2.10424480932041E-05"
        ixy="-7.6027356652029E-12"
        ixz="3.47651138429731E-12"
        iyy="8.34117266397957E-06"
        iyz="-7.48309280558843E-07"
        izz="2.49437221252633E-05" />
    </inertial>
    <visual>
      <origin
        xyz="0 0 0"
        rpy="0 0 0" />
      <geometry>
        <mesh
          filename="package://ASM-1/meshes/Empty_Link3-5.STL" />
      </geometry>
      <material
        name="">
        <color
          rgba="0.752941176470588 0.752941176470588 0.752941176470588 1" />
      </material>
    </visual>
    <collision>
      <origin
        xyz="0 0 0"
        rpy="0 0 0" />
      <geometry>
        <mesh
          filename="package://ASM-1/meshes/Empty_Link3-5.STL" />
      </geometry>
    </collision>
  </link>
  <joint
    name="joint3-5"
    type="revolute">
    <origin
      xyz="0 0.094 0"
      rpy="-1.5708 0 0" />
    <parent
      link="Empty_Link2-5" />
    <child
      link="Empty_Link3-5" />
    <axis
      xyz="-1 0 0" />
    <limit
      lower="-1.57"
      upper="1.57"
      effort="0"
      velocity="0" />
  </joint>
  <link
    name="Empty_Link1-6">
    <inertial>
      <origin
        xyz="-5.02346878693063E-05 0.0330000000000002 -5.02346878692612E-05"
        rpy="0 0 0" />
      <mass
        value="0.019731071348658" />
      <inertia
        ixx="9.77086440607926E-06"
        ixy="2.9159908347244E-08"
        ixz="1.25162983602224E-19"
        iyy="1.23734036568865E-05"
        iyz="-2.91599083472426E-08"
        izz="9.77086440607926E-06" />
    </inertial>
    <visual>
      <origin
        xyz="0 0 0"
        rpy="0 0 0" />
      <geometry>
        <mesh
          filename="package://ASM-1/meshes/Empty_Link1-6.STL" />
      </geometry>
      <material
        name="">
        <color
          rgba="0.752941176470588 0.752941176470588 0.752941176470588 1" />
      </material>
    </visual>
    <collision>
      <origin
        xyz="0 0 0"
        rpy="0 0 0" />
      <geometry>
        <mesh
          filename="package://ASM-1/meshes/Empty_Link1-6.STL" />
      </geometry>
    </collision>
  </link>
  <joint
    name="joint1-6"
    type="revolute">
    <origin
      xyz="0.12051 -0.065506 0"
      rpy="0 0 -2.3562" />
    <parent
      link="base" />
    <child
      link="Empty_Link1-6" />
    <axis
      xyz="0 0 -1" />
    <limit
      lower="-1.05"
      upper="1.05"
      effort="0"
      velocity="0" />
  </joint>
  <link
    name="Empty_Link2-6">
    <inertial>
      <origin
        xyz="-2.25108720576656E-05 0.047 0.000657512135363084"
        rpy="0 0 0" />
      <mass
        value="0.0736108086784939" />
      <inertia
        ixx="1.27657759015739E-05"
        ixy="-8.470329472543E-22"
        ixz="1.06896458574625E-21"
        iyy="1.39088073615343E-05"
        iyz="3.63365746510252E-11"
        izz="2.1644430327163E-05" />
    </inertial>
    <visual>
      <origin
        xyz="0 0 0"
        rpy="0 0 0" />
      <geometry>
        <mesh
          filename="package://ASM-1/meshes/Empty_Link2-6.STL" />
      </geometry>
      <material
        name="">
        <color
          rgba="0.752941176470588 0.752941176470588 0.752941176470588 1" />
      </material>
    </visual>
    <collision>
      <origin
        xyz="0 0 0"
        rpy="0 0 0" />
      <geometry>
        <mesh
          filename="package://ASM-1/meshes/Empty_Link2-6.STL" />
      </geometry>
    </collision>
  </link>
  <joint
    name="joint2-6"
    type="revolute">
    <origin
      xyz="0 0.066 0"
      rpy="0 0 0" />
    <parent
      link="Empty_Link1-6" />
    <child
      link="Empty_Link2-6" />
    <axis
      xyz="-1 0 0" />
    <limit
      lower="-1.57"
      upper="1.57"
      effort="0"
      velocity="0" />
  </joint>
  <link
    name="Empty_Link3-6">
    <inertial>
      <origin
        xyz="4.99966688657094E-05 0.0900463290285193 0.0104437249548177"
        rpy="0 0 0" />
      <mass
        value="0.0425517554776167" />
      <inertia
        ixx="2.10424480740807E-05"
        ixy="-7.59739058626184E-12"
        ixz="3.47413321001518E-12"
        iyy="8.34117254759518E-06"
        iyz="-7.48309278499955E-07"
        izz="2.49437219866352E-05" />
    </inertial>
    <visual>
      <origin
        xyz="0 0 0"
        rpy="0 0 0" />
      <geometry>
        <mesh
          filename="package://ASM-1/meshes/Empty_Link3-6.STL" />
      </geometry>
      <material
        name="">
        <color
          rgba="0.752941176470588 0.752941176470588 0.752941176470588 1" />
      </material>
    </visual>
    <collision>
      <origin
        xyz="0 0 0"
        rpy="0 0 0" />
      <geometry>
        <mesh
          filename="package://ASM-1/meshes/Empty_Link3-6.STL" />
      </geometry>
    </collision>
  </link>
  <joint
    name="joint3-6"
    type="revolute">
    <origin
      xyz="0 0.094 0"
      rpy="-1.5708 0 0" />
    <parent
      link="Empty_Link2-6" />
    <child
      link="Empty_Link3-6" />
    <axis
      xyz="-1 0 0" />
    <limit
      lower="-1.57"
      upper="1.57"
      effort="0"
      velocity="0" />
  </joint>
</robot>