<robot
  name="ur3">
  <link
    name="base_link">
    <inertial>
      <origin
        xyz="3.9271E-05 0.04622 0.00080839"
        rpy="0 0 0" />
      <mass
        value="0.61579" />
      <inertia
        ixx="0.00079865"
        ixy="9.7917E-07"
        ixz="-1.4612E-06"
        iyy="0.001032"
        iyz="1.9027E-05"
        izz="0.00078297" />
    </inertial>
    <visual>
      <origin
        xyz="0 0 0"
        rpy="0 0 0" />
      <geometry>
        <mesh
          filename="package://ur3/meshes/base_link.STL" />
      </geometry>
      <material
        name="">
        <color
          rgba="1 1 1 1" />
      </material>
    </visual>
    <collision>
      <origin
        xyz="0 0 0"
        rpy="0 0 0" />
      <geometry>
        <mesh
          filename="package://ur3/meshes/base_link.STL" />
      </geometry>
    </collision>
  </link>
  <link
    name="link1">
    <inertial>
      <origin
        xyz="-1.0714E-05 0.055942 0.0073314"
        rpy="0 0 0" />
      <mass
        value="0.75586" />
      <inertia
        ixx="0.0012076"
        ixy="1.5182E-07"
        ixz="1.1041E-07"
        iyy="0.00091335"
        iyz="-0.00010158"
        izz="0.0011222" />
    </inertial>
    <visual>
      <origin
        xyz="0 0 0"
        rpy="0 0 0" />
      <geometry>
        <mesh
          filename="package://ur3/meshes/link1.STL" />
      </geometry>
      <material
        name="">
        <color
          rgba="1 1 1 1" />
      </material>
    </visual>
    <collision>
      <origin
        xyz="0 0 0"
        rpy="0 0 0" />
      <geometry>
        <mesh
          filename="package://ur3/meshes/link1.STL" />
      </geometry>
    </collision>
  </link>
  <joint
    name="joint1"
    type="revolute">
    <origin
      xyz="0 0 0.0844"
      rpy="1.5708 5.6655E-16 -3.1416" />
    <parent
      link="base_link" />
    <child
      link="link1" />
    <axis
      xyz="0 1 0" />
    <limit
      lower="-3.14"
      upper="3.14"
      effort="100"
      velocity="1" />
  </joint>
  <link
    name="link2">
    <inertial>
      <origin
        xyz="-4.188E-06 0.064249 0.1057"
        rpy="0 0 0" />
      <mass
        value="1.8019" />
      <inertia
        ixx="0.01936"
        ixy="8.8945E-08"
        ixz="-7.4473E-07"
        iyy="0.018785"
        iyz="-0.0013523"
        izz="0.0021134" />
    </inertial>
    <visual>
      <origin
        xyz="0 0 0"
        rpy="0 0 0" />
      <geometry>
        <mesh
          filename="package://ur3/meshes/link2.STL" />
      </geometry>
      <material
        name="">
        <color
          rgba="1 1 1 1" />
      </material>
    </visual>
    <collision>
      <origin
        xyz="0 0 0"
        rpy="0 0 0" />
      <geometry>
        <mesh
          filename="package://ur3/meshes/link2.STL" />
      </geometry>
    </collision>
  </link>
  <joint
    name="joint2"
    type="revolute">
    <origin
      xyz="0 0.0675 0.05235"
      rpy="1.5708 0 -3.1416" />
    <parent
      link="link1" />
    <child
      link="link2" />
    <axis
      xyz="0 -1 0" />
    <limit
      lower="-3.14"
      upper="3.14"
      effort="100"
      velocity="1" />
  </joint>
  <link
    name="link3">
    <inertial>
      <origin
        xyz="-0.0051445 -0.1112 7.0153E-08"
        rpy="0 0 0" />
      <mass
        value="0.96225" />
      <inertia
        ixx="0.0071078"
        ixy="0.00058643"
        ixz="8.7729E-10"
        iyy="0.00067153"
        iyz="5.7985E-09"
        izz="0.0072945" />
    </inertial>
    <visual>
      <origin
        xyz="0 0 0"
        rpy="0 0 0" />
      <geometry>
        <mesh
          filename="package://ur3/meshes/link3.STL" />
      </geometry>
      <material
        name="">
        <color
          rgba="1 1 1 1" />
      </material>
    </visual>
    <collision>
      <origin
        xyz="0 0 0"
        rpy="0 0 0" />
      <geometry>
        <mesh
          filename="package://ur3/meshes/link3.STL" />
      </geometry>
    </collision>
  </link>
  <joint
    name="joint3"
    type="revolute">
    <origin
      xyz="0 -0.02535 0.24365"
      rpy="-1.5708 7.4983E-33 -1.5708" />
    <parent
      link="link2" />
    <child
      link="link3" />
    <axis
      xyz="1 0 0" />
    <limit
      lower="-3.14"
      upper="3.14"
      effort="100"
      velocity="1" />
  </joint>
  <link
    name="link4">
    <inertial>
      <origin
        xyz="0.0059213 -0.00051763 2.6076E-07"
        rpy="0 0 0" />
      <mass
        value="0.32523" />
      <inertia
        ixx="0.00026155"
        ixy="1.7566E-06"
        ixz="-1.985E-09"
        iyy="0.00020549"
        iyz="-4.0128E-10"
        izz="0.00029955" />
    </inertial>
    <visual>
      <origin
        xyz="0 0 0"
        rpy="0 0 0" />
      <geometry>
        <mesh
          filename="package://ur3/meshes/link4.STL" />
      </geometry>
      <material
        name="">
        <color
          rgba="1 1 1 1" />
      </material>
    </visual>
    <collision>
      <origin
        xyz="0 0 0"
        rpy="0 0 0" />
      <geometry>
        <mesh
          filename="package://ur3/meshes/link4.STL" />
      </geometry>
    </collision>
  </link>
  <joint
    name="joint4"
    type="revolute">
    <origin
      xyz="-0.0834 -0.213 0"
      rpy="-3.1416 -4.9304E-32 -7.4983E-33" />
    <parent
      link="link3" />
    <child
      link="link4" />
    <axis
      xyz="1 0 0" />
    <limit
      lower="-3.14"
      upper="3.14"
      effort="100"
      velocity="1" />
  </joint>
  <link
    name="link5">
    <inertial>
      <origin
        xyz="0.0059213 0.00051762 -2.3715E-07"
        rpy="0 0 0" />
      <mass
        value="0.32523" />
      <inertia
        ixx="0.00026155"
        ixy="-1.7566E-06"
        ixz="1.9216E-09"
        iyy="0.00020549"
        iyz="-2.2402E-10"
        izz="0.00029955" />
    </inertial>
    <visual>
      <origin
        xyz="0 0 0"
        rpy="0 0 0" />
      <geometry>
        <mesh
          filename="package://ur3/meshes/link5.STL" />
      </geometry>
      <material
        name="">
        <color
          rgba="1 1 1 1" />
      </material>
    </visual>
    <collision>
      <origin
        xyz="0 0 0"
        rpy="0 0 0" />
      <geometry>
        <mesh
          filename="package://ur3/meshes/link5.STL" />
      </geometry>
    </collision>
  </link>
  <joint
    name="joint5"
    type="revolute">
    <origin
      xyz="0 0.0834 0"
      rpy="0 -3.8286E-16 -1.5708" />
    <parent
      link="link4" />
    <child
      link="link5" />
    <axis
      xyz="-1 0 0" />
    <limit
      lower="-3.14"
      upper="3.14"
      effort="100"
      velocity="1" />
  </joint>
  <link
    name="link6">
    <inertial>
      <origin
        xyz="-3.468E-11 0.00010331 -0.021073"
        rpy="0 0 0" />
      <mass
        value="0.11536" />
      <inertia
        ixx="4.3204E-05"
        ixy="5.7806E-13"
        ixz="-1.2E-12"
        iyy="4.3416E-05"
        iyz="1.0813E-07"
        izz="5.9067E-05" />
    </inertial>
    <visual>
      <origin
        xyz="0 0 0"
        rpy="0 0 0" />
      <geometry>
        <mesh
          filename="package://ur3/meshes/link6.STL" />
      </geometry>
      <material
        name="">
        <color
          rgba="1 1 1 1" />
      </material>
    </visual>
    <collision>
      <origin
        xyz="0 0 0"
        rpy="0 0 0" />
      <geometry>
        <mesh
          filename="package://ur3/meshes/link6.STL" />
      </geometry>
    </collision>
  </link>
  <joint
    name="joint6"
    type="revolute">
    <origin
      xyz="0 -0.0409 0"
      rpy="1.5708 -1.5708 0" />
    <parent
      link="link5" />
    <child
      link="link6" />
    <axis
      xyz="0 0 1" />
    <limit
      lower="-3.14"
      upper="3.14"
      effort="100"
      velocity="1" />
  </joint>
</robot>